<?xml version="1.0" ?>
<robot xmlns:xacro="http://www.ros.org/wiki/xacro" 
 name="duco_gcr5">
<!-- base_link -->
<link name="base_link">
    <visual>
      <origin rpy="0 0 0" xyz="0 0 0"/>
      <geometry>
        <mesh filename="package://duco_support/meshes/GCR5/base_link.stl"/>
      </geometry>
      <material name ="Gray"/>
    </visual>
   <collision>
      <origin rpy="0 0 0" xyz="0 0 0"/>
      <geometry>
        <mesh filename="package://duco_support/collision/GCR5/base_link.stl"/>
      </geometry>
    </collision>
  </link>
<!-- link_1 -->
<link name="link_1">
    <visual>
      <origin rpy="0 0 0" xyz="0 0 0"/>
      <geometry>
        <mesh filename="package://duco_support/meshes/GCR5/link_1.stl"/>
      </geometry>
      <material name ="Blue"/>
    </visual>
    <collision>
      <origin rpy="0 0 0" xyz="0 0 0"/>
      <geometry>
        <mesh filename="package://duco_support/collision/GCR5/link_1.stl"/>
      </geometry>
    </collision>
    <inertial>
      <mass value="12.369"/>
      <inertia ixx="0.069552066" ixy="0.000045456" ixz="0.000067368" iyy="0.0682463" iyz="0.000262322" izz="0.054371276"/>
    </inertial>
  </link>
<!-- joint_1 -->
<joint name="joint_1" type="revolute">
    <origin rpy="0 0 0" xyz="0 0 0.122"/>
    <parent link="base_link"/>
    <child link="link_1"/>
    <axis xyz="0 0 1"/>
    <limit effort="140" lower="${-pi}" upper="${pi}" velocity="${65*pi/180}"/>
  </joint>
<!-- link_2 -->
<link name="link_2">
    <visual>
      <origin rpy="0 0 0" xyz="0 0 0"/>
      <geometry>
        <mesh filename="package://duco_support/meshes/GCR5/link_2.stl"/>
      </geometry>
      <material name ="Gray"/>
    </visual>
    <collision>
      <origin rpy="0 0 0" xyz="0 0 0"/>
      <geometry>
        <mesh filename="package://duco_support/collision/GCR5/link_2.stl"/>
      </geometry>
    </collision>
    <inertial>
       <mass value="22.51"/>
      <inertia ixx="0.093854855" ixy="0.000013115" ixz="0.068806066" iyy="2.128374674" iyz="-0.000013033" izz="2.120185065"/>
    </inertial>
  </link>
<!-- joint_2 -->
<joint name="joint_2" type="revolute">
    <origin rpy="-1.5707963 -1.5707963 0" xyz="0 0.1405 0"/>
    <parent link="link_1"/>
    <child link="link_2"/>
    <axis xyz="0 0 1"/>
    <limit effort="140" lower="${-pi}" upper="${pi}" velocity="${65*pi/180}"/>
  </joint>

<!-- link_3 -->
<link name="link_3">
    <visual>
      <origin rpy="0 0 0" xyz="0 0 0"/>
      <geometry>
        <mesh filename="package://duco_support/meshes/GCR5/link_3.stl"/>
      </geometry>
     <material name ="Blue"/>
    </visual>
    <collision>
      <origin rpy="0 0 0" xyz="0 0 0"/>
      <geometry>
        <mesh filename="package://duco_support/collision/GCR5/link_3.stl"/>
      </geometry>
    </collision>
    <inertial>
      <origin rpy="0 0 0" xyz="0.000000 0.000000 0.000000"/>
      <mass value="6.386"/>
      <inertia ixx="0.104318273" ixy="-0.00039878" ixz="-0.227010136" iyy="0.956648365" iyz="0.000204575" izz="0.867868815"/>
    </inertial>
  </link>
<!-- joint_3 -->
<joint name="joint_3" type="revolute">
    <origin rpy="0 0 0" xyz="0.425 0 0"/>
    <parent link="link_2"/>
    <child link="link_3"/>
    <axis xyz="0 0 1"/>
    <limit effort="140.0" lower="${-160/180*pi}" upper="${160/180*pi}" velocity="${105*pi/180}"/>
  </joint>
<!-- link_4 -->
<link name="link_4">
    <visual>
      <origin rpy="0 0 0" xyz="0 0 0"/>
      <geometry>
        <mesh filename="package://duco_support/meshes/GCR5/link_4.stl"/>
      </geometry>
      <material name ="Gray"/>
    </visual>
    <collision>
      <origin rpy="0 0 0" xyz="0 0 0"/>
      <geometry>
        <mesh filename="package://duco_support/collision/GCR5/link_4.stl"/>
      </geometry>
    </collision>
    <inertial>
      <origin rpy="0 0 0" xyz="0.000000 0.000000 0.000000"/>
      <mass value="3.579"/>
      <inertia ixx="0.010470895" ixy="0.000061784" ixz="0.00000228" iyy="0.006243529" iyz="-0.000040702" izz="0.010424802"/>
    </inertial>
  </link>
<!-- joint_4 -->
<joint name="joint_4" type="revolute">
    <origin rpy="0 0 1.5707963" xyz="0.392 0 0"/>
    <parent link="link_3"/>
    <child link="link_4"/>
    <axis xyz="0 0 1"/>
    <limit effort="140" lower="${-pi}" upper="${pi}" velocity="${165*pi/180}"/>
  </joint>
<!-- link_5 -->
<link name="link_5">
    <visual>
      <origin rpy="0 0 0" xyz="0 0 0"/>
      <geometry>
        <mesh filename="package://duco_support/meshes/GCR5/link_5.stl"/>
      </geometry>
     <material name ="Blue"/>
    </visual>
    <collision>
      <origin rpy="0 0 0" xyz="0 0 0"/>
      <geometry>
        <mesh filename="package://duco_support/collision/GCR5/link_5.stl"/>
      </geometry>
    </collision>
    <inertial>
      <origin rpy="0 0 0" xyz="0.000000 0.000000 0.000000"/>
      <mass value="3.579"/>
      <inertia ixx="0.010470895" ixy="0.000061784" ixz="-0.00000228" iyy="0.006243529" iyz="0.000040702" izz="0.010424802"/>
    </inertial>
  </link>
<!-- joint_5 -->
<joint name="joint_5" type="revolute">
    <origin rpy="1.5707963 0 0" xyz="0 -0.1 0"/>
    <parent link="link_4"/>
    <child link="link_5"/>
    <axis xyz="0 0 1"/>
    <limit effort="140.0" lower="${-pi}" upper="${pi}" velocity="${165*pi/180}"/>
  </joint>
<!-- link_6 -->
<link name="link_6">
    <visual>
      <origin rpy="0 0 0" xyz="0 0 0"/>
      <geometry>
        <mesh filename="package://duco_support/meshes/GCR5/link_6.stl"/>
      </geometry>
      <material name ="Red"/>
    </visual>
    <collision>
      <origin rpy="0 0 0" xyz="0 0 0"/>
      <geometry>
        <mesh filename="package://duco_support/collision/GCR5/link_6.stl"/>
      </geometry>
    </collision>
    <inertial>
      <origin rpy="0 0 0" xyz="0.000000 0.000000 0.000000"/>
      <mass value="0.477"/>
      <inertia ixx="0.000742141" ixy="0.000000009" ixz="-0.000010713" iyy="0.000761498" iyz="0.000004274" izz="0.001029656"/>
    </inertial>
  </link>
<!-- joint_6 -->
<joint name="joint_6" type="revolute">
    <origin rpy="-1.5707963 0 0" xyz="0 0.094 0"/>
    <parent link="link_5"/>
    <child link="link_6"/>
    <axis xyz="0 0 1"/>
    <limit effort="140.0" lower="${-pi}" upper="${pi}" velocity="${165*pi/180}"/>
  </joint>


</robot>
