<?xml version="1.0" encoding="utf-8"?>
<!-- This URDF was automatically created by SolidWorks to URDF Exporter! Originally created by Stephen Brawner (brawner@gmail.com) 
     Commit Version: 1.6.0-4-g7f85cfe  Build Version: 1.6.7995.38578
     For more information, please see http://wiki.ros.org/sw_urdf_exporter -->
<robot
  name="gcr10">
  <link
    name="base_link">
    <inertial>
      <origin
        xyz="5.4538E-05 0.0034249 0.036769"
        rpy="0 0 0" />
      <mass
        value="2.112" />
      <inertia
        ixx="0.010998"
        ixy="2.636E-05"
        ixz="3.0192E-06"
        iyy="0.012303"
        iyz="0.0003209"
        izz="0.01834" />
    </inertial>
    <visual>
      <origin
        xyz="0 0 0"
        rpy="0 0 0" />
      <geometry>
        <mesh
          filename="package://gcr10/meshes/base_link.STL" />
      </geometry>
      <material
        name="">
        <color
          rgba="0.73333 0.78039 0.83922 1" />
      </material>
    </visual>
    <collision>
      <origin
        xyz="0 0 0"
        rpy="0 0 0" />
      <geometry>
        <mesh
          filename="package://gcr10/meshes/base_link.STL" />
      </geometry>
    </collision>
  </link>
  <link
    name="link_1">
    <inertial>
      <origin
        xyz="-8.0724E-06 0.020679 -0.00033859"
        rpy="0 0 0" />
      <mass
        value="9.174" />
      <inertia
        ixx="0.011236"
        ixy="-6.1939E-07"
        ixz="1.2924E-06"
        iyy="0.0099752"
        iyz="-0.00041415"
        izz="0.0096564" />
    </inertial>
    <visual>
      <origin
        xyz="0 0 0"
        rpy="0 0 0" />
      <geometry>
        <mesh
          filename="package://gcr10/meshes/link_1.STL" />
      </geometry>
      <material
        name="">
        <color
          rgba="0.73333 0.78039 0.83922 1" />
      </material>
    </visual>
    <collision>
      <origin
        xyz="0 0 0"
        rpy="0 0 0" />
      <geometry>
        <mesh
          filename="package://gcr10/meshes/link_1.STL" />
      </geometry>
    </collision>
  </link>
  <joint
    name="joint_1"
    type="revolute">
    <origin
      xyz="0 0 0.165"
      rpy="0 0 0" />
    <parent
      link="base_link" />
    <child
      link="link_1" />
    <axis
      xyz="0 0 1" />
    <limit
      lower="-3.14"
      upper="3.14"
      effort="250"
      velocity="180" />
  </joint>
  <link
    name="link_2">
    <inertial>
      <origin
        xyz="0.24003 2.6017E-05 0.023044"
        rpy="0 0 0" />
      <mass
        value="16.09" />
      <inertia
        ixx="0.0067857"
        ixy="1.0599E-06"
        ixz="-0.0066714"
        iyy="0.099673"
        iyz="-3.9289E-06"
        izz="0.097884" />
    </inertial>
    <visual>
      <origin
        xyz="0 0 0"
        rpy="0 0 0" />
      <geometry>
        <mesh
          filename="package://gcr10/meshes/link_2.STL" />
      </geometry>
      <material
        name="">
        <color
          rgba="0.79216 0.81961 0.93333 1" />
      </material>
    </visual>
    <collision>
      <origin
        xyz="0 0 0"
        rpy="0 0 0" />
      <geometry>
        <mesh
          filename="package://gcr10/meshes/link_2.STL" />
      </geometry>
    </collision>
  </link>
  <joint
    name="joint_2"
    type="revolute">
    <origin
      xyz="0 0.164 0"
      rpy="1.5708 -1.5708 3.1416" />
    <parent
      link="link_1" />
    <child
      link="link_2" />
    <axis
      xyz="0 0 1" />
    <limit
      lower="-3.14"
      upper="3.14"
      effort="250"
      velocity="180" />
  </joint>
  <link
    name="link_3">
    <inertial>
      <origin
        xyz="0.36057 -0.00034711 -0.11352"
        rpy="0 0 0" />
      <mass
        value="4.765" />
      <inertia
        ixx="0.0027111"
        ixy="-6.1841E-06"
        ixz="9.6878E-05"
        iyy="0.0066917"
        iyz="6.1421E-06"
        izz="0.0057171" />
    </inertial>
    <visual>
      <origin
        xyz="0 0 0"
        rpy="0 0 0" />
      <geometry>
        <mesh
          filename="package://gcr10/meshes/link_3.STL" />
      </geometry>
      <material
        name="">
        <color
          rgba="0.86667 0.86667 0.8902 1" />
      </material>
    </visual>
    <collision>
      <origin
        xyz="0 0 0"
        rpy="0 0 0" />
      <geometry>
        <mesh
          filename="package://gcr10/meshes/link_3.STL" />
      </geometry>
    </collision>
  </link>
  <joint
    name="joint_3"
    type="revolute">
    <origin
      xyz="0.608 0 0"
      rpy="0 0 0" />
    <parent
      link="link_2" />
    <child
      link="link_3" />
    <axis
      xyz="0 0 1" />
    <limit
      lower="-3.14"
      upper="3.14"
      effort="150"
      velocity="225" />
  </joint>
  <link
    name="link_4">
    <inertial>
      <origin
        xyz="-5.1722E-06 -0.016972 -0.0089368"
        rpy="0 0 0" />
      <mass
        value="2.485" />
      <inertia
        ixx="0.002539"
        ixy="2.1074E-07"
        ixz="-1.9525E-07"
        iyy="0.0016933"
        iyz="0.00014476"
        izz="0.0022871" />
    </inertial>
    <visual>
      <origin
        xyz="0 0 0"
        rpy="0 0 0" />
      <geometry>
        <mesh
          filename="package://gcr10/meshes/link_4.STL" />
      </geometry>
      <material
        name="">
        <color
          rgba="0.86667 0.86667 0.8902 1" />
      </material>
    </visual>
    <collision>
      <origin
        xyz="0 0 0"
        rpy="0 0 0" />
      <geometry>
        <mesh
          filename="package://gcr10/meshes/link_4.STL" />
      </geometry>
    </collision>
  </link>
  <joint
    name="joint_4"
    type="revolute">
    <origin
      xyz="0.566 0 0"
      rpy="0 0 1.5708" />
    <parent
      link="link_3" />
    <child
      link="link_4" />
    <axis
      xyz="0 0 1" />
    <limit
      lower="-3.14"
      upper="3.14"
      effort="50"
      velocity="225" />
  </joint>
  <link
    name="link_5">
    <inertial>
      <origin
        xyz="5.1964E-06 0.016972 -0.0089368"
        rpy="0 0 0" />
      <mass
        value="2.485" />
      <inertia
        ixx="0.002539"
        ixy="2.1126E-07"
        ixz="1.9517E-07"
        iyy="0.0016933"
        iyz="-0.00014476"
        izz="0.0022871" />
    </inertial>
    <visual>
      <origin
        xyz="0 0 0"
        rpy="0 0 0" />
      <geometry>
        <mesh
          filename="package://gcr10/meshes/link_5.STL" />
      </geometry>
      <material
        name="">
        <color
          rgba="0.86667 0.86667 0.8902 1" />
      </material>
    </visual>
    <collision>
      <origin
        xyz="0 0 0"
        rpy="0 0 0" />
      <geometry>
        <mesh
          filename="package://gcr10/meshes/link_5.STL" />
      </geometry>
    </collision>
  </link>
  <joint
    name="joint_5"
    type="revolute">
    <origin
      xyz="0 -0.126 0"
      rpy="1.5708 0 0" />
    <parent
      link="link_4" />
    <child
      link="link_5" />
    <axis
      xyz="0 0 1" />
    <limit
      lower="-3.14"
      upper="3.14"
      effort="50"
      velocity="225" />
  </joint>
  <link
    name="link_6">
    <inertial>
      <origin
        xyz="9.1186E-16 -6.6613E-16 -0.024173"
        rpy="0 0 0" />
      <mass
        value="0.451" />
      <inertia
        ixx="0.00044067"
        ixy="2.9825E-20"
        ixz="-2.9705E-19"
        iyy="0.00044067"
        iyz="-5.2285E-20"
        izz="0.00077308" />
    </inertial>
    <visual>
      <origin
        xyz="0 0 0"
        rpy="0 0 0" />
      <geometry>
        <mesh
          filename="package://gcr10/meshes/link_6.STL" />
      </geometry>
      <material
        name="">
        <color
          rgba="0.86667 0.86667 0.8902 1" />
      </material>
    </visual>
    <collision>
      <origin
        xyz="0 0 0"
        rpy="0 0 0" />
      <geometry>
        <mesh
          filename="package://gcr10/meshes/link_6.STL" />
      </geometry>
    </collision>
  </link>
  <joint
    name="joint_6"
    type="revolute">
    <origin
      xyz="0 0.113 0"
      rpy="-1.5708 0 0" />
    <parent
      link="link_5" />
    <child
      link="link_6" />
    <axis
      xyz="0 0 1" />
    <limit
      lower="-3.14"
      upper="3.14"
      effort="50"
      velocity="225" />
  </joint>
</robot>